Workbook
Name _GET_MITIGATION_TYPE_COL: LAMBDA(type, IF(type="Physical", 6, IF(type="Magical", 5, IF(type="Darkness", 7, 7))))
Name _TRANS: LAMBDA(translate, jp, en, de, fr, ko, cn, IFERROR(IFS(translate="日本語", jp, translate="English", en, translate="Deutsch", de, translate="Français", fr, translate="한국어", ko, translate="简体中文", cn), jp))
Name _GET_TANK_ATTACHED_BUFF_TYPE_COL: LAMBDA(type, IF(type="Physical", 7, IF(type="Magical", 6, IF(type="Darkness", 8, 8))))

Sheet Skill
B2: Role / Job | C2: Skill | D2: Icon | E2: Level | F2: Effect Time | G2: Recast | H2: Abillity | I2: Assign | J2: Charge | K2: Mitigation Time | L2: Magic | M2: Physical | N2: Unique | O2: Block | P2: Parry | Q2: Critical Mitigation Time | R2: Magic | S2: Physical | T2: Unique | U2: Precondition | V2: Recast | W2: Magic | X2: Physical | Y2: Unique | Z2: More Heal | AA2: Barrier Time | AB2: More Barrier | AC2: HP Buff Time | AD2: HP Buffed | AE2: Heal Buff Target | AF2: Heal Buff Time | AG2: Add Heal Buffed | AH2: Times Heal Buffed | AI2: Barrier Buff Time | AJ2: Barrier Buffed | AK2: Heal | AL2: Heal Raito | AM2: Hot Time | AN2: Hot | AO2: Barrier Time | AP2: Barrior | AQ2: MP | AR2: Available Skill Time | AS2: Available Skill | AT2: Timer Shared | AU2: Icon Path | AV2: EN | AW2: DE | AX2: FR | AY2: KO | AZ2: CN
B3: 学者 | C3: セラフィズム | D3: =IMAGE(AU3) | E3: 100 | F3: 20 | G3: 180 | H3: TRUE | I3: SELF | J3: 1 | AM3: 20 | AN3: 100 | AU3: https://xivapi.com/i/002000/002881.png | AV3: Seraphism | AW3: Seraphenlehre | AX3: Séraphisme
B4: 学者 | C4: アクセッション | D4: =IMAGE(AU4) | E4: 100 | F4: 30 | G4: 2.5 | H4: FALSE | I4: RANGE_PARTY | J4: 1 | AK4: 240 | AO4: 30 | AP4: 432 | AQ4: 900 | AR4: 20 | AS4: セラフィズム | AU4: https://xivapi.com/i/002000/002883.png | AV4: Accession | AW4: Höchstes Gut | AX4: Accession
B5: 学者 | C5: マニフェステーション | D5: =IMAGE(AU5) | E5: 100 | F5: 30 | G5: 2.5 | H5: FALSE | I5: SINGLE_PARTY | J5: 1 | U5: 秘策 | AA5: 30 | AB5: 648 | AK5: 360 | AO5: 30 | AP5: 648 | AQ5: 900 | AR5: 20 | AS5: セラフィズム | AU5: https://xivapi.com/i/002000/002882.png | AV5: Manifestation | AW5: Manifestation | AX5: Manifestation
B6: 賢者 | C6: フィロソフィア | D6: =IMAGE(AU6) | E6: 100 | F6: 20 | G6: 180 | H6: TRUE | I6: RANGE_PARTY | J6: 1 | AE6: SELF_EFFECTED_GCD | AF6: 20 | AH6: 1.2 | AU6: https://xivapi.com/i/003000/003690.png | AV6: Philosophia | AW6: Philosophia | AX6: Philosophia
B7: 占星術師 | C7: サンサイン | D7: =IMAGE(AU7) | E7: 100 | F7: 15 | G7: 1 | H7: TRUE | I7: RANGE_PARTY | J7: 1 | K7: 15 | L7: 0.9 | M7: 0.9 | N7: 0.9 | AR7: 30 | AS7: ニュートラルセクト | AU7: https://xivapi.com/i/003000/003109.png | AV7: Sun Sign | AW7: Sonnenzeichen | AX7: Signe solaire
B8: 白魔道士 | C8: ディヴァインカレス | D8: =IMAGE(AU8) | E8: 100 | F8: 10 | G8: 1 | H8: FALSE | I8: RANGE_PARTY | J8: 1 | AM8: 15 | AN8: 200 | AO8: 10 | AP8: 400 | AR8: 30 | AS8: テンパランス | AU8: https://xivapi.com/i/002000/002128.png | AV8: Divine Caress | AW8: Göttliche Umarmung | AX8: Caresse divine
B9: 学者 | C9: 秘策 | D9: =IMAGE(AU9) | E9: 98 | F9: 15 | G9: 60 | H9: TRUE | I9: SINGLE_PARTY | J9: 1 | AU9: https://xivapi.com/i/002000/002822.png | AV9: Recitation | AW9: Raffinesse | AX9: Récitation | AY9: 비책 | AZ9: 秘策
B10: キャスター | C10: アドル | D10: =IMAGE(AU10) | E10: 98 | F10: 15 | G10: 90 | H10: TRUE | I10: SINGLE_ENEMY | J10: 1 | K10: 15 | L10: 0.9 | M10: 0.95 | N10: 1 | AU10: https://xivapi.com/i/000000/000861.png | AV10: Addle | AW10: Stumpfsinn | AX10: Embrouillement | AY10: 정신 교란 | AZ10: 昏乱
B11: タンク | C11: リプライザル | D11: =IMAGE(AU11) | E11: 98 | F11: 15 | G11: 60 | H11: TRUE | I11: RANGE_ENEMY | J11: 1 | K11: 15 | L11: 0.9 | M11: 0.9 | N11: 0.9 | AU11: https://xivapi.com/i/000000/000806.png | AV11: Reprisal | AW11: Reflexion | AX11: Rétorsion | AY11: 앙갚음 | AZ11: 雪仇
B12: 機工士 | C12: タクティシャン | D12: =IMAGE(AU12) | E12: 98 | F12: 15 | G12: 90 | H12: TRUE | I12: RANGE_PARTY | J12: 1 | K12: 15 | L12: 0.85 | M12: 0.85 | N12: 0.85 | AU12: https://xivapi.com/i/003000/003040.png | AV12: Tactician | AW12: Taktiker | AX12: Tacticien | AY12: 책략가 | AZ12: 策动
B13: 近接 | C13: 牽制 | D13: =IMAGE(AU13) | E13: 98 | F13: 15 | G13: 90 | H13: TRUE | I13: SINGLE_ENEMY | J13: 1 | K13: 15 | L13: 0.95 | M13: 0.9 | N13: 1 | AU13: https://xivapi.com/i/000000/000828.png | AV13: Feint | AW13: Zermürben | AX13: Restreinte | AY13: 견제 | AZ13: 牵制
B14: 吟遊詩人 | C14: トルバドゥール | D14: =IMAGE(AU14) | E14: 98 | F14: 15 | G14: 90 | H14: TRUE | I14: RANGE_PARTY | J14: 1 | K14: 15 | L14: 0.85 | M14: 0.85 | N14: 0.85 | AU14: https://xivapi.com/i/002000/002612.png | AV14: Troubadour | AW14: Troubadour | AX14: Troubadour | AY14: 방랑하는 음악가 | AZ14: 行吟
B15: 賢者 | C15: ピュシスII | D15: =IMAGE(AU15) | E15: 98 | F15: 15 | G15: 60 | H15: TRUE | I15: RANGE_PARTY | J15: 1 | AE15: RANGE_AFFECTED_ALL | AF15: 15 | AH15: 1.1 | AM15: 15 | AN15: 130 | AU15: https://xivapi.com/i/003000/003670.png | AV15: Physis II | AW15: Physis II | AX15: Physis II | AY15: 퓌시스 2 | AZ15: 自生II
B16: 占星術師 | C16: ディグニティ(最小) | D16: =IMAGE(AU16) | E16: 98 | F16: 0 | G16: 40 | H16: TRUE | I16: SINGLE_PARTY | J16: 3 | AK16: 400 | AU16: https://xivapi.com/i/003000/003141.png | AV16: Essential Dignity(minimum) | AW16: Essenzielle Würde(minimum) | AX16: Dignité essentielle(le minimum) | AY16: 본질적 위계(최소) | AZ16: 先天禀赋(最低限度)
B17: 占星術師 | C17: ディグニティ(最大) | D17: =IMAGE(AU17) | E17: 98 | F17: 0 | G17: 40 | H17: TRUE | I17: SINGLE_PARTY | J17: 3 | AK17: 900 | AU17: https://xivapi.com/i/003000/003141.png | AV17: Essential Dignity(maximum) | AW17: Essenzielle Würde(maximal) | AX17: Dignité essentielle(maximum) | AY17: 본질적 위계(최대) | AZ17: 先天禀赋(最大)
B18: 白魔道士 | C18: テトラグラマトン | D18: =IMAGE(AU18) | E18: 98 | F18: 0 | G18: 60 | H18: TRUE | I18: SINGLE_PARTY | J18: 2 | AK18: 700 | AU18: https://xivapi.com/i/002000/002633.png | AV18: Tetragrammaton | AW18: Tetragrammaton | AX18: Tétragramme | AY18: 신의 이름 | AZ18: 神名
B19: 踊り子 | C19: 守りのサンバ | D19: =IMAGE(AU19) | E19: 98 | F19: 15 | G19: 90 | H19: TRUE | I19: RANGE_PARTY | J19: 1 | K19: 15 | L19: 0.85 | M19: 0.85 | N19: 0.85 | AU19: https://xivapi.com/i/003000/003469.png | AV19: Shield Samba | AW19: Schildsamba | AX19: Samba protectrice | AY19: 수세의 삼바 | AZ19: 防守之桑巴
B20: 学者 | C20: 意気軒昂の策 | D20: =IMAGE(AU20) | E20: 96 | F20: 30 | G20: 2.5 | H20: FALSE | I20: RANGE_PARTY | J20: 1 | AK20: 200 | AO20: 30 | AP20: 360 | AQ20: 900 | AU20: https://xivapi.com/i/002000/002880.png | AV20: Concitation | AW20: Übermut | AX20: Traité de l'exultation
B21: 賢者 | C21: エウクラシア・プログノシスII | D21: =IMAGE(AU21) | E21: 96 | F21: 30 | G21: 2.5 | H21: FALSE | I21: RANGE_PARTY | J21: 1 | AK21: 100 | AO21: 30 | AP21: 360 | AQ21: 800 | AU21: https://xivapi.com/i/003000/003689.png | AV21: Eukrasian Prognosis II | AW21: Eukratische Prognose II | AX21: Prognosis eucrasique II
B22: 占星術師 | C22: コンジャクション・ヘリオス | D22: =IMAGE(AU22) | E22: 96 | F22: 15 | G22: 2.5 | H22: FALSE | I22: RANGE_PARTY | J22: 1 | U22: ニュートラルセクト | AA22: 30 | AB22: 312.5 | AK22: 250 | AM22: 15 | AN22: 175 | AU22: https://xivapi.com/i/003000/003567.png | AV22: Helios Conjunction | AW22: Helios in Konjunktion | AX22: Hélios combiné
B23: タンク | C23: ランパート | D23: =IMAGE(AU23) | E23: 94 | F23: 20 | G23: 90 | H23: TRUE | I23: SELF | J23: 1 | K23: 20 | L23: 0.8 | M23: 0.8 | N23: 0.8 | AE23: SELF_AFFECTED_ALL | AF23: 20 | AH23: 1.15 | AU23: https://xivapi.com/i/000000/000801.png | AV23: Rampart | AW23: Schutzwall | AX23: Rempart | AY23: 철벽 방어 | AZ23: 铁壁
B24: ガンブレイカー | C24: グレートネビュラ | D24: =IMAGE(AU24) | E24: 92 | F24: 15 | G24: 120 | H24: TRUE | I24: SELF | J24: 1 | K24: 15 | L24: 0.6 | M24: 0.6 | N24: 0.6 | AC24: 15 | AD24: 1.2 | AL24: 0.2 | AU24: https://xivapi.com/i/003000/003435.png | AV24: Great Nebula | AW24: Große Nebula | AX24: Grande nébuleuse
B25: ナイト | C25: エクストリームガード | D25: =IMAGE(AU25) | E25: 92 | F25: 15 | G25: 120 | H25: TRUE | I25: SELF | J25: 1 | K25: 15 | L25: 0.6 | M25: 0.6 | N25: 0.6 | AO25: 15 | AP25: 1000 | AU25: https://xivapi.com/i/002000/002524.png | AV25: Guardian | AW25: Heilige Wacht | AX25: Garde extrême
B26: 暗黒騎士 | C26: シャドウヴィジル | D26: =IMAGE(AU26) | E26: 92 | F26: 15 | G26: 120 | H26: TRUE | I26: SELF | J26: 1 | K26: 15 | L26: 0.6 | M26: 0.6 | N26: 0.6 | AK26: 1200 | AU26: https://xivapi.com/i/003000/003094.png | AV26: Shadowed Vigil | AW26: Schattenwacht | AX26: Vigile ténébreux
B27: 戦士 | C27: ダムネーション | D27: =IMAGE(AU27) | E27: 92 | F27: 15 | G27: 120 | H27: TRUE | I27: SELF | J27: 1 | K27: 15 | L27: 0.6 | M27: 0.6 | N27: 0.6 | AM27: 15 | AN27: 400 | AU27: https://xivapi.com/i/002000/002573.png | AV27: Damnation | AW27: Verdammnis | AX27: Damnation
B28: 白魔道士 | C28: メディガ | D28: =IMAGE(AU28) | E28: 92 | F28: 15 | G28: 2.5 | H28: FALSE | I28: RANGE_PARTY | J28: 1 | U28: インドゥルゲンティア | Z28: 450 | AK28: 250 | AM28: 15 | AN28: 175 | AQ28: 1000 | AU28: https://xivapi.com/i/002000/002127.png | AV28: Medica III | AW28: Resega | AX28: Méga Médica
B29: 学者 | C29: 疾風怒濤の計 | D29: =IMAGE(AU29) | E29: 90 | F29: 20 | G29: 120 | H29: TRUE | I29: RANGE_PARTY | J29: 1 | K29: 20 | L29: 0.9 | M29: 0.9 | N29: 0.9 | AU29: https://xivapi.com/i/002000/002878.png | AV29: Expedient | AW29: Sturm und Drang | AX29: Thèse fluidique | AY29: 질풍노도계 | AZ29: 疾风怒涛之计
B30: 賢者 | C30: プネウマ | D30: =IMAGE(AU30) | E30: 90 | F30: 0 | G30: 120 | H30: TRUE | I30: RANGE_PARTY | J30: 1 | AK30: 600 | AQ30: 700 | AU30: https://xivapi.com/i/003000/003686.png | AV30: Pneuma | AW30: Pneuma | AX30: Pneuma | AY30: 프네우마 | AZ30: 魂灵风息
B31: 占星術師 | C31: マクロコスモス(最小) | D31: =IMAGE(AU31) | E31: 90 | F31: 0 | G31: 180 | H31: TRUE | I31: RANGE_PARTY | J31: 1 | AK31: 200 | AU31: https://xivapi.com/i/003000/003562.png | AV31: Macrocosmos(minimum) | AW31: Makrokosmos(minimum) | AX31: Macrocosme(le minimum) | AY31: 대우주(최소) | AZ31: 大宇宙(最低限度)
B32: 占星術師 | C32: マクロコスモス(被ダメ50%分) | D32: =IMAGE(AU32) | E32: 90 | F32: 0 | G32: 180 | H32: TRUE | I32: RANGE_PARTY | J32: 1 | AU32: https://xivapi.com/i/003000/003562.png | AV32: Macrocosmos(50% damage received) | AW32: Makrokosmos(50 % erlittener Schaden) | AX32: Macrocosme(50 % de dégâts reçus) | AY32: 대우주(피 안 50%) | AZ32: 大宇宙(受到 50% 的伤害)
B33: 白魔道士 | C33: リタージー・オブ・ベル(ダメージトリガー) | D33: =IMAGE(AU33) | E33: 90 | F33: 0 | G33: 180 | H33: TRUE | I33: RANGE_PARTY | J33: 1 | AK33: 400 | AU33: https://xivapi.com/i/002000/002649.png | AV33: Liturgy of the Bell(damage trigger) | AW33: Glockenspiel(Schaden auslösen) | AX33: Tintinnabule(déclencheur de dégâts) | AY33: 예배종(데미지 트리거) | AZ33: 礼仪之铃(伤害触发)
B34: 白魔道士 | C34: リタージー・オブ・ベル(時間経過:残1) | D34: =IMAGE(AU34) | E34: 90 | F34: 0 | G34: 180 | H34: TRUE | I34: RANGE_PARTY | J34: 1 | AK34: 200 | AU34: https://xivapi.com/i/002000/002649.png | AV34: Liturgy of the Bell(Time Lapse: Stack 1) | AW34: Glockenspiel(Zeitraffer: Stapel 1) | AX34: Tintinnabule(Time Lapse : Pile 1) | AY34: 예배종(시간 경과 : 스택 1) | AZ34: 礼仪之铃(延时摄影：堆栈 1)
B35: 白魔道士 | C35: リタージー・オブ・ベル(時間経過:残2) | D35: =IMAGE(AU35) | E35: 90 | F35: 0 | G35: 180 | H35: TRUE | I35: RANGE_PARTY | J35: 1 | AK35: 400 | AU35: https://xivapi.com/i/002000/002649.png | AV35: Liturgy of the Bell(Time Lapse: Stack 2) | AW35: Glockenspiel(Zeitraffer: Stapel 2) | AX35: Tintinnabule(Time Lapse : Pile 2) | AY35: 예배종(시간 경과 : 스택 2) | AZ35: 礼仪之铃(延时摄影：堆栈 2)
B36: 白魔道士 | C36: リタージー・オブ・ベル(時間経過:残3) | D36: =IMAGE(AU36) | E36: 90 | F36: 0 | G36: 180 | H36: TRUE | I36: RANGE_PARTY | J36: 1 | AK36: 600 | AU36: https://xivapi.com/i/002000/002649.png | AV36: Liturgy of the Bell(Time Lapse: Stack 3) | AW36: Glockenspiel(Zeitraffer: Stapel 3) | AX36: Tintinnabule(Time Lapse : Pile 3) | AY36: 예배종(시간 경과 : 스택 3) | AZ36: 礼仪之铃(延时摄影：堆栈 3)
B37: 白魔道士 | C37: リタージー・オブ・ベル(時間経過:残4) | D37: =IMAGE(AU37) | E37: 90 | F37: 0 | G37: 180 | H37: TRUE | I37: RANGE_PARTY | J37: 1 | AK37: 800 | AU37: https://xivapi.com/i/002000/002649.png | AV37: Liturgy of the Bell(Time Lapse: Stack 4) | AW37: Glockenspiel(Zeitraffer: Stapel 4) | AX37: Tintinnabule(Time Lapse : Pile 4) | AY37: 예배종(시간 경과 : 스택 4) | AZ37: 礼仪之铃(延时摄影：堆栈 4)
B38: 白魔道士 | C38: リタージー・オブ・ベル(時間経過:残5) | D38: =IMAGE(AU38) | E38: 90 | F38: 0 | G38: 180 | H38: TRUE | I38: RANGE_PARTY | J38: 1 | AK38: 1000 | AU38: https://xivapi.com/i/002000/002649.png | AV38: Liturgy of the Bell(Time Lapse: Stack 5) | AW38: Glockenspiel(Zeitraffer: Stapel 5) | AX38: Tintinnabule(Time Lapse : Pile 5) | AY38: 예배종(시간 경과 : 스택 5) | AZ38: 礼仪之铃(延时摄影：堆栈 5)
B39: ナイト | C39: ディヴァインヴェール | D39: =IMAGE(AU39) | E39: 88 | F39: 30 | G39: 90 | H39: TRUE | I39: RANGE_PARTY | J39: 1 | AI39: 30 | AJ39: 0.1 | AK39: 400 | AU39: https://xivapi.com/i/002000/002508.png | AV39: Divine Veil | AW39: Heiliger Quell | AX39: Voile divin | AY39: 신성한 보호막 | AZ39: 圣光幕帘
B40: ピクトマンサー | C40: テンペラグラッサ | D40: =IMAGE(AU40) | E40: 88 | F40: 10 | G40: 1 | H40: TRUE | I40: SELF | J40: 1 | AI40: 10 | AJ40: 0.1 | AR40: 10 | AU40: https://xivapi.com/i/003000/003836.png | AV40: Tempera Grassa | AW40: Fette Tempera | AX40: Tempera grassa
B41: 学者 | C41: 展開戦術 | D41: =IMAGE(AU41) | E41: 88 | F41: 0 | G41: 90 | H41: TRUE | I41: RANGE_PARTY | J41: 1 | AU41: https://xivapi.com/i/002000/002808.png | AV41: Deployment Tactics | AW41: Dislokation | AX41: Stratagème du déploiement | AY41: 전개전술 | AZ41: 展开战术
...

Sheet Phase 1
AM1: wa
B2: Phase | C2: Total Time | D2: Time | E2: Action | F2: Type | G2: Type | H2: Damage | I2: Damage | J2: Damage | K2: Mitigation | L2: Mitigation | M2: Barrier | N2: Mitigation | O2: Mitigation | P2: Mitigation | Q2: Mitigation | R2: Mitigation | S2: Mitigation | T2: Mitigation | U2: Barrier | V2: Mitigation | W2: Mitigation | X2: Mitigation | Y2: Mitigation | Z2: Mitigation | AA2: Heal | AB2: Mitigation | AC2: Mitigation | AD2: Mitigation | AE2: Barrier | AF2: Mitigation | AG2: Mitigation | AH2: Mitigation | AI2: Mitigation | AJ2: Mitigation | AK2: Mitigation | AL2: Mitigation | AM2: Mitigation | AN2: Mitigation | AO2: Mitigation | AP2: Mitigation | AQ2: Mitigation | AR2: Mitigation | AS2: Mitigation | AT2: Barrier | AU2: Heal | AV2: Heal | AW2: Heal | AX2: Heal | AY2: Mitigation | AZ2: Barrier | BA2: Barrier | BB2: Heal | BC2: Heal | BD2: Heal | BE2: Mitigation | BF2: Heal | BG2: Mitigation | BH2: Barrier | BI2: Heal | BJ2: Heal | BK2: Heal | BL2: Heal | BM2: Mitigation | BN2: Mitigation | BO2: Mitigation | BP2: Mitigation | BQ2: Mitigation | BR2: Mitigation | BS2: Heal | BT2: Heal | BU2: Mitigation | BV2: Barrier | BW2: Barrier | BX2: Barrier | BY2: Mitigation | BZ2: Mitigation | CA2: Mitigation | CB2: Barrier | CC2: Barrier | CD2: Heal | CE2: Heal | CF2: Heal | CG2: Barrier | CH2: Barrier | CI2: Heal | CJ2: Heal | CK2: Mitigation | CL2: Barrier | CM2: Barrier | CN2: Heal | CO2: Mitigation | CP2: Barrier | CQ2: Barrier | CR2: Heal | CT2: Mitigation | CU2: Mitigation | CV2: Barrier | CW2: Barrier | CX2: Heal | CY2: Heal | CZ2: Heal | DA2: Heal | DB2: Heal | DC2: Heal | DD2: Heal | DE2: Mitigation | DF2: Barrier | DG2: Barrier | DH2: Heal | DJ2: Mitigation | DK2: Heal | DL2: Mitigation | DM2: Mitigation | DN2: Mitigation | DO2: Mitigation | DP2: Mitigation | DQ2: Mitigation | DR2: Heal | DS2: Mitigation | DT2: Mitigation | DU2: Mitigation | DV2: Barrier | DW2: Mitigation | DX2: Mitigation | DY2: Mitigation | DZ2: Mitigation | EA2: Mitigation | EB2: Barrier | EC2: Barrier | ED2: Mitigation | EE2: Mitigation | EF2: Heal | EG2: Heal | EH2: Heal | EI2: Heal | EJ2: Heal | EK2: Heal | EL2: Heal | EM2: Heal | EN2: Heal | EO2: Heal | EP2: Mitigation | EQ2: Barrier | ER2: Damage | ES2: Damage | EU2: Mitigation | EV2: Mitigation | EW2: Heal | EX2: Barrier | EZ2: Mitigation | FA2: Mitigation | FB2: Heal | FC2: Barrier | FE2: Mitigation | FF2: Mitigation | FG2: Heal | FH2: Barrier | FJ2: Mitigation | FK2: Mitigation | FL2: Heal | FM2: Barrier
B3: =Option!$C6 -> TRUE | C3: {=IFERROR(INDEX('Phase Map'!$E$2:$E$12, MATCH(E3, 'Phase Map'!$C$2:$C$12, 0)), "hide")} | E3: =GETSHEETNAME() -> Phase 1 | F3: hide | K3: ナイト | L3: ナイト | M3: ナイト | N3: ナイト | O3: ナイト | P3: ナイト | Q3: ナイト | R3: ナイト | S3: ナイト | T3: 戦士 | U3: 戦士 | V3: 戦士 | W3: 戦士 | X3: 戦士 | Y3: 戦士 | Z3: 戦士 | AA3: 戦士 | AB3: 戦士 | AC3: 暗黒騎士 | AD3: 暗黒騎士 | AE3: 暗黒騎士 | AF3: 暗黒騎士 | AG3: hide | AH3: 暗黒騎士 | AI3: 暗黒騎士 | AJ3: 暗黒騎士 | AK3: 暗黒騎士 | AL3: ガンブレイカー | AM3: ガンブレイカー | AN3: ガンブレイカー | AO3: ガンブレイカー | AP3: ガンブレイカー | AQ3: ガンブレイカー | AR3: ガンブレイカー | AS3: 白魔道士 | AT3: 白魔道士 | AU3: 白魔道士 | AV3: 白魔道士 | AW3: 白魔道士 | AX3: 白魔道士 | AY3: 白魔道士 | AZ3: 白魔道士 | BA3: hide | BB3: 白魔道士 | BC3: hide | BD3: 白魔道士 | BE3: 占星術師 | BF3: 占星術師 | BG3: 占星術師 | BH3: 占星術師 | BI3: 占星術師 | BJ3: 占星術師 | BK3: 占星術師 | BL3: 占星術師 | BM3: 占星術師 | BN3: 占星術師 | BO3: 占星術師 | BP3: 占星術師 | BQ3: 占星術師 | BR3: 占星術師 | BS3: 占星術師 | BT3: hide | BU3: 占星術師 | BV3: 占星術師 | BW3: hide | BX3: 占星術師 | BY3: 学者 | BZ3: 学者 | CA3: 学者 | CB3: 学者 | CC3: 学者 | CD3: 学者 | CE3: 学者 | CF3: 学者 | CG3: 学者 | CH3: 学者 | CI3: 学者 | CJ3: 学者 | CK3: 学者 | CL3: 学者 | CM3: 学者 | CN3: 学者 | CO3: 学者 | CP3: 学者 | CQ3: 学者 | CR3: 学者 | CS3: 学者 | CT3: 賢者 | CU3: 賢者 | CV3: 賢者 | CW3: 賢者 | CX3: 賢者 | CY3: 賢者 | CZ3: 賢者 | DA3: 賢者 | DB3: 賢者 | DC3: 賢者 | DD3: 賢者 | DE3: 賢者 | DF3: 賢者 | DG3: 賢者 | DH3: 賢者 | DI3: 賢者 | DJ3: モンク | DK3: モンク | DL3: 竜騎士 | DM3: 忍者 | DN3: 侍 | DO3: リーパー | DP3: ヴァイパー | DQ3: 吟遊詩人 | DR3: 吟遊詩人 | DS3: 機工士 | DT3: 機工士 | DU3: 踊り子 | DV3: 踊り子 | DW3: 黒魔道士 | DX3: 召喚士 | DY3: 赤魔道士 | DZ3: 赤魔道士 | EA3: ピクトマンサー | EB3: ピクトマンサー | EC3: ピクトマンサー | ED3: タンク | EE3: hide | EF3: hide | EG3: hide | EH3: hide | EI3: hide | EJ3: hide | EK3: hide | EL3: hide | EM3: hide | EN3: hide | EO3: hide | EP3: hide | EQ3: hide | EU3: hide | EV3: hide | EW3: hide | EX3: hide | EY3: ナイト | EZ3: hide | FA3: hide | FB3: hide | FC3: hide | FD3: 戦士 | FE3: hide | FF3: hide | FG3: hide | FH3: hide | FI3: 暗黒騎士 | FJ3: hide | FK3: hide | FL3: hide | FM3: hide | FN3: ガンブレイカー
B4: =Option!$C7 -> TRUE | C4: {=IFERROR(INDEX('Phase Map'!$D$2:$D$12, MATCH(E3, 'Phase Map'!$C$2:$C$12, 0)), "")} -> 0.0017013889 | E4: Skill | K4: リプライザル | L4: パッセージ・オブ・アームズ | M4: ディヴァインヴェール | N4: インターベンション | O4: ランパート | P4: ブルワーク | Q4: エクストリームガード | R4: ホーリーシェルトロン | S4: インビンシブル | T4: リプライザル | U4: シェイクオフ | V4: 原初の猛り | W4: ランパート | X4: スリル・オブ・バトル | Y4: ダムネーション | Z4: 原初の血気 | AA4: エクリブリウム | AB4: ホルムギャング | AC4: リプライザル | AD4: ダークミッショナリー | AE4: ブラックナイト | AF4: オブレーション | AH4: ランパート | AI4: ダークマインド | AJ4: シャドウヴィジル | AK4: リビングデッド | AL4: リプライザル | AM4: ハート・オブ・ライト | AN4: ハート・オブ・コランダム | AO4: ランパート | AP4: カモフラージュ | AQ4: グレートネビュラ | AR4: ボーライド | AS4: テンパランス | AT4: ディヴァインカレス | AU4: インドゥルゲンティア | AV4: アサイラム | AW4: アサイズ | AX4: リタージー・オブ・ベル(ダメージトリガー) | AY4: アクアヴェール | AZ4: ディヴァインベニゾン | BB4: テトラグラマトン | BD4: ベネディクション | BE4: 運命の輪 | BF4: ニュートラルセクト | BG4: サンサイン | BH4: コンジャクション・ヘリオス | BI4: 星天対抗 | BJ4: アーサリースター(星の支配者) | BK4: ホロスコープ | BL4: マクロコスモス(最小) | BM4: アストラルドロー | BN4: アンブラルドロー | BO4: オシュオンの矢 | BP4: ビエルゴの塔 | BQ4: 世界樹の幹 | BR4: サリャクの水瓶 | BS4: ディグニティ(最小) | BU4: エクザルテーション | BV4: 星天交差 | BX4: アスペクト・ベネフィク | BY4: フェイイルミネーション | BZ4: 野戦治療の陣 | CA4: 疾風怒濤の計 | CB4: 展開戦術 | CC4: 意気軒昂の策 | CD4: 光の囁き | CE4: 不撓不屈の策 | CF4: フェイブレッシング | CG4: サモン・セラフィム | CH4: コンソレイション | CI4: 転化 | CJ4: 秘策 | CK4: セラフィズム | CL4: アクセッション | CM4: マニフェステーション | CN4: 生命活性法 | CO4: 生命回生法 | CP4: 鼓舞激励の策 | CQ4: 深謀遠慮の策 | CR4: エーテルフロー | CT4: ホーリズム | CU4: ケーラコレ | CV4: エウクラシア・プログノシスII | CW4: パンハイマ | CX4: ゾーエ | CY4: ピュシスII | CZ4: イックソコレ | DA4: ペプシス(エウクラシア・ディアグノシス) | DB4: プネウマ | DC4: フィロソフィア | DD4: ドルオコレ | DE4: タウロコレ | DF4: エウクラシア・ディアグノシス | DG4: ハイマ | DH4: リゾーマタ | DJ4: 牽制 | DK4: マントラ | DL4: 牽制 | DM4: 牽制 | DN4: 牽制 | DO4: 牽制 | DP4: 牽制 | DQ4: トルバドゥール | DR4: 地神のミンネ | DS4: タクティシャン | DT4: ウェポンブレイク | DU4: 守りのサンバ | DV4: インプロビゼーションフィニッシュ(踊りの激情0) | DW4: アドル | DX4: アドル | DY4: アドル | DZ4: バマジク | EA4: アドル | EB4: テンペラコート | EC4: テンペラグラッサ | ED4: LB3
B5: =Option!$C8 -> TRUE | C5: {=IFERROR(INDEX('Phase Map'!$C$3:$C$13, MATCH(E3, 'Phase Map'!$C$2:$C$12, 0)), "")} -> Phase 2 | E5: Assign | K5: {=IFERROR(INDEX(Skill!$I:$I, MATCH(K$4, Skill!$C:$C, 0), 1), "")} -> RANGE_ENEMY | L5: {=IFERROR(INDEX(Skill!$I:$I, MATCH(L$4, Skill!$C:$C, 0), 1), "")} -> RANGE_PARTY | M5: {=IFERROR(INDEX(Skill!$I:$I, MATCH(M$4, Skill!$C:$C, 0), 1), "")} -> RANGE_PARTY | N5: {=IFERROR(INDEX(Skill!$I:$I, MATCH(N$4, Skill!$C:$C, 0), 1), "")} -> SINGLE_PARTY | O5: {=IFERROR(INDEX(Skill!$I:$I, MATCH(O$4, Skill!$C:$C, 0), 1), "")} -> SELF | P5: {=IFERROR(INDEX(Skill!$I:$I, MATCH(P$4, Skill!$C:$C, 0), 1), "")} -> SELF | Q5: {=IFERROR(INDEX(Skill!$I:$I, MATCH(Q$4, Skill!$C:$C, 0), 1), "")} -> SELF | R5: {=IFERROR(INDEX(Skill!$I:$I, MATCH(R$4, Skill!$C:$C, 0), 1), "")} -> SELF | ... ED5: {=IFERROR(INDEX(Skill!$I:$I, MATCH(ED$4, Skill!$C:$C, 0), 1), "")} -> RANGE_PARTY
B6: =Option!$C9 -> TRUE | E6: Charge | K6: {=IFERROR(INDEX(Skill!$J:$J, MATCH(K$4, Skill!$C:$C, 0), 1), "")} -> 1 | L6: {=IFERROR(INDEX(Skill!$J:$J, MATCH(L$4, Skill!$C:$C, 0), 1), "")} -> 1 | M6: {=IFERROR(INDEX(Skill!$J:$J, MATCH(M$4, Skill!$C:$C, 0), 1), "")} -> 1 | N6: {=IFERROR(INDEX(Skill!$J:$J, MATCH(N$4, Skill!$C:$C, 0), 1), "")} -> 1 | O6: {=IFERROR(INDEX(Skill!$J:$J, MATCH(O$4, Skill!$C:$C, 0), 1), "")} -> 1 | P6: {=IFERROR(INDEX(Skill!$J:$J, MATCH(P$4, Skill!$C:$C, 0), 1), "")} -> 1 | Q6: {=IFERROR(INDEX(Skill!$J:$J, MATCH(Q$4, Skill!$C:$C, 0), 1), "")} -> 1 | R6: {=IFERROR(INDEX(Skill!$J:$J, MATCH(R$4, Skill!$C:$C, 0), 1), "")} -> 1 | ... ED6: {=IFERROR(INDEX(Skill!$J:$J, MATCH(ED$4, Skill!$C:$C, 0), 1), "")} -> 1
E7: Abillity | K7: {=IFERROR(INDEX(Skill!$H:$H, MATCH(K$4, Skill!$C:$C, 0), 1), "")} -> TRUE | L7: {=IFERROR(INDEX(Skill!$H:$H, MATCH(L$4, Skill!$C:$C, 0), 1), "")} -> TRUE | M7: {=IFERROR(INDEX(Skill!$H:$H, MATCH(M$4, Skill!$C:$C, 0), 1), "")} -> TRUE | N7: {=IFERROR(INDEX(Skill!$H:$H, MATCH(N$4, Skill!$C:$C, 0), 1), "")} -> TRUE | O7: {=IFERROR(INDEX(Skill!$H:$H, MATCH(O$4, Skill!$C:$C, 0), 1), "")} -> TRUE | P7: {=IFERROR(INDEX(Skill!$H:$H, MATCH(P$4, Skill!$C:$C, 0), 1), "")} -> TRUE | Q7: {=IFERROR(INDEX(Skill!$H:$H, MATCH(Q$4, Skill!$C:$C, 0), 1), "")} -> TRUE | R7: {=IFERROR(INDEX(Skill!$H:$H, MATCH(R$4, Skill!$C:$C, 0), 1), "")} -> TRUE | ... ED7: {=IFERROR(INDEX(Skill!$H:$H, MATCH(ED$4, Skill!$C:$C, 0), 1), "")} -> FALSE
E8: Time | K8: {=IFERROR(INDEX(Skill!$F:$F, MATCH(K$4, Skill!$C:$C, 0), 1), "")} -> 15 | L8: {=IFERROR(INDEX(Skill!$F:$F, MATCH(L$4, Skill!$C:$C, 0), 1), "")} -> 18 | M8: {=IFERROR(INDEX(Skill!$F:$F, MATCH(M$4, Skill!$C:$C, 0), 1), "")} -> 30 | N8: {=IFERROR(INDEX(Skill!$F:$F, MATCH(N$4, Skill!$C:$C, 0), 1), "")} -> 8 | O8: {=IFERROR(INDEX(Skill!$F:$F, MATCH(O$4, Skill!$C:$C, 0), 1), "")} -> 20 | P8: {=IFERROR(INDEX(Skill!$F:$F, MATCH(P$4, Skill!$C:$C, 0), 1), "")} -> 10 | Q8: {=IFERROR(INDEX(Skill!$F:$F, MATCH(Q$4, Skill!$C:$C, 0), 1), "")} -> 15 | R8: {=IFERROR(INDEX(Skill!$F:$F, MATCH(R$4, Skill!$C:$C, 0), 1), "")} -> 8 | ... ED8: {=IFERROR(INDEX(Skill!$F:$F, MATCH(ED$4, Skill!$C:$C, 0), 1), "")} -> 8
E9: Recast | K9: {=IFERROR(INDEX(Skill!$G:$G, MATCH(K$4, Skill!$C:$C, 0), 1), "")} -> 60 | L9: {=IFERROR(INDEX(Skill!$G:$G, MATCH(L$4, Skill!$C:$C, 0), 1), "")} -> 120 | M9: {=IFERROR(INDEX(Skill!$G:$G, MATCH(M$4, Skill!$C:$C, 0), 1), "")} -> 90 | N9: {=IFERROR(INDEX(Skill!$G:$G, MATCH(N$4, Skill!$C:$C, 0), 1), "")} -> 10 | O9: {=IFERROR(INDEX(Skill!$G:$G, MATCH(O$4, Skill!$C:$C, 0), 1), "")} -> 90 | P9: {=IFERROR(INDEX(Skill!$G:$G, MATCH(P$4, Skill!$C:$C, 0), 1), "")} -> 90 | Q9: {=IFERROR(INDEX(Skill!$G:$G, MATCH(Q$4, Skill!$C:$C, 0), 1), "")} -> 120 | R9: {=IFERROR(INDEX(Skill!$G:$G, MATCH(R$4, Skill!$C:$C, 0), 1), "")} -> 5 | ... ED9: {=IFERROR(INDEX(Skill!$G:$G, MATCH(ED$4, Skill!$C:$C, 0), 1), "")} -> 2.5
E10: Physical | K10: {=IFERROR(INDEX(Skill!$M:$M, MATCH(K$4, Skill!$C:$C, 0), 1), "")} -> 0.9 | L10: {=IFERROR(INDEX(Skill!$M:$M, MATCH(L$4, Skill!$C:$C, 0), 1), "")} -> 0.85 | M10: {=IFERROR(INDEX(Skill!$M:$M, MATCH(M$4, Skill!$C:$C, 0), 1), "")} | N10: {=IFERROR(INDEX(Skill!$M:$M, MATCH(N$4, Skill!$C:$C, 0), 1), "")} -> 0.9 | O10: {=IFERROR(INDEX(Skill!$M:$M, MATCH(O$4, Skill!$C:$C, 0), 1), "")} -> 0.8 | P10: {=IFERROR(INDEX(Skill!$M:$M, MATCH(P$4, Skill!$C:$C, 0), 1), "")} | Q10: {=IFERROR(INDEX(Skill!$M:$M, MATCH(Q$4, Skill!$C:$C, 0), 1), "")} -> 0.6 | R10: {=IFERROR(INDEX(Skill!$M:$M, MATCH(R$4, Skill!$C:$C, 0), 1), "")} -> 0.85 | ... ED10: {=IFERROR(INDEX(Skill!$M:$M, MATCH(ED$4, Skill!$C:$C, 0), 1), "")} -> 0.2
E11: Magic | K11: {=IFERROR(INDEX(Skill!$L:$L, MATCH(K$4, Skill!$C:$C, 0), 1), "")} -> 0.9 | L11: {=IFERROR(INDEX(Skill!$L:$L, MATCH(L$4, Skill!$C:$C, 0), 1), "")} -> 0.85 | M11: {=IFERROR(INDEX(Skill!$L:$L, MATCH(M$4, Skill!$C:$C, 0), 1), "")} | N11: {=IFERROR(INDEX(Skill!$L:$L, MATCH(N$4, Skill!$C:$C, 0), 1), "")} -> 0.9 | O11: {=IFERROR(INDEX(Skill!$L:$L, MATCH(O$4, Skill!$C:$C, 0), 1), "")} -> 0.8 | P11: {=IFERROR(INDEX(Skill!$L:$L, MATCH(P$4, Skill!$C:$C, 0), 1), "")} | Q11: {=IFERROR(INDEX(Skill!$L:$L, MATCH(Q$4, Skill!$C:$C, 0), 1), "")} -> 0.6 | R11: {=IFERROR(INDEX(Skill!$L:$L, MATCH(R$4, Skill!$C:$C, 0), 1), "")} -> 0.85 | ... ED11: {=IFERROR(INDEX(Skill!$L:$L, MATCH(ED$4, Skill!$C:$C, 0), 1), "")} -> 0.2
E12: Unique | K12: {=IFERROR(INDEX(Skill!$N:$N, MATCH(K$4, Skill!$C:$C, 0), 1), "")} -> 0.9 | L12: {=IFERROR(INDEX(Skill!$N:$N, MATCH(L$4, Skill!$C:$C, 0), 1), "")} -> 0.85 | M12: {=IFERROR(INDEX(Skill!$N:$N, MATCH(M$4, Skill!$C:$C, 0), 1), "")} | N12: {=IFERROR(INDEX(Skill!$N:$N, MATCH(N$4, Skill!$C:$C, 0), 1), "")} -> 0.9 | O12: {=IFERROR(INDEX(Skill!$N:$N, MATCH(O$4, Skill!$C:$C, 0), 1), "")} -> 0.8 | P12: {=IFERROR(INDEX(Skill!$N:$N, MATCH(P$4, Skill!$C:$C, 0), 1), "")} | Q12: {=IFERROR(INDEX(Skill!$N:$N, MATCH(Q$4, Skill!$C:$C, 0), 1), "")} -> 0.6 | R12: {=IFERROR(INDEX(Skill!$N:$N, MATCH(R$4, Skill!$C:$C, 0), 1), "")} -> 0.85 | ... ED12: {=IFERROR(INDEX(Skill!$N:$N, MATCH(ED$4, Skill!$C:$C, 0), 1), "")} -> 0.2
E13: Heal Buff Target | K13: {=IFERROR(INDEX(Skill!$AE:$AE, MATCH(K$4, Skill!$C:$C, 0), 1), "")} | L13: {=IFERROR(INDEX(Skill!$AE:$AE, MATCH(L$4, Skill!$C:$C, 0), 1), "")} | M13: {=IFERROR(INDEX(Skill!$AE:$AE, MATCH(M$4, Skill!$C:$C, 0), 1), "")} | N13: {=IFERROR(INDEX(Skill!$AE:$AE, MATCH(N$4, Skill!$C:$C, 0), 1), "")} | O13: {=IFERROR(INDEX(Skill!$AE:$AE, MATCH(O$4, Skill!$C:$C, 0), 1), "")} -> SELF_AFFECTED_ALL | P13: {=IFERROR(INDEX(Skill!$AE:$AE, MATCH(P$4, Skill!$C:$C, 0), 1), "")} | Q13: {=IFERROR(INDEX(Skill!$AE:$AE, MATCH(Q$4, Skill!$C:$C, 0), 1), "")} | R13: {=IFERROR(INDEX(Skill!$AE:$AE, MATCH(R$4, Skill!$C:$C, 0), 1), "")} | ... ED13: {=IFERROR(INDEX(Skill!$AE:$AE, MATCH(ED$4, Skill!$C:$C, 0), 1), "")}
E14: Heal Buff | K14: {=IFERROR(INDEX(Skill!$AH:$AH, MATCH(K$4, Skill!$C:$C, 0), 1), "")} | L14: {=IFERROR(INDEX(Skill!$AH:$AH, MATCH(L$4, Skill!$C:$C, 0), 1), "")} | M14: {=IFERROR(INDEX(Skill!$AH:$AH, MATCH(M$4, Skill!$C:$C, 0), 1), "")} | N14: {=IFERROR(INDEX(Skill!$AH:$AH, MATCH(N$4, Skill!$C:$C, 0), 1), "")} | O14: {=IFERROR(INDEX(Skill!$AH:$AH, MATCH(O$4, Skill!$C:$C, 0), 1), "")} -> 1.15 | P14: {=IFERROR(INDEX(Skill!$AH:$AH, MATCH(P$4, Skill!$C:$C, 0), 1), "")} | Q14: {=IFERROR(INDEX(Skill!$AH:$AH, MATCH(Q$4, Skill!$C:$C, 0), 1), "")} | R14: {=IFERROR(INDEX(Skill!$AH:$AH, MATCH(R$4, Skill!$C:$C, 0), 1), "")} | ... ED14: {=IFERROR(INDEX(Skill!$AH:$AH, MATCH(ED$4, Skill!$C:$C, 0), 1), "")}
E15: Barrier Buff | K15: {=IFERROR(INDEX(Skill!$AJ:$AJ, MATCH(K$4, Skill!$C:$C, 0), 1), "")} | L15: {=IFERROR(INDEX(Skill!$AJ:$AJ, MATCH(L$4, Skill!$C:$C, 0), 1), "")} | M15: {=IFERROR(INDEX(Skill!$AJ:$AJ, MATCH(M$4, Skill!$C:$C, 0), 1), "")} -> 0.1 | N15: {=IFERROR(INDEX(Skill!$AJ:$AJ, MATCH(N$4, Skill!$C:$C, 0), 1), "")} | O15: {=IFERROR(INDEX(Skill!$AJ:$AJ, MATCH(O$4, Skill!$C:$C, 0), 1), "")} | P15: {=IFERROR(INDEX(Skill!$AJ:$AJ, MATCH(P$4, Skill!$C:$C, 0), 1), "")} | Q15: {=IFERROR(INDEX(Skill!$AJ:$AJ, MATCH(Q$4, Skill!$C:$C, 0), 1), "")} | R15: {=IFERROR(INDEX(Skill!$AJ:$AJ, MATCH(R$4, Skill!$C:$C, 0), 1), "")} | ... ED15: {=IFERROR(INDEX(Skill!$AJ:$AJ, MATCH(ED$4, Skill!$C:$C, 0), 1), "")}
E16: Barrier | K16: {=IFERROR(INDEX(Skill!$AP:$AP, MATCH(K$4, Skill!$C:$C, 0), 1), "")} | L16: {=IFERROR(INDEX(Skill!$AP:$AP, MATCH(L$4, Skill!$C:$C, 0), 1), "")} | M16: {=IFERROR(INDEX(Skill!$AP:$AP, MATCH(M$4, Skill!$C:$C, 0), 1), "")} | N16: {=IFERROR(INDEX(Skill!$AP:$AP, MATCH(N$4, Skill!$C:$C, 0), 1), "")} | O16: {=IFERROR(INDEX(Skill!$AP:$AP, MATCH(O$4, Skill!$C:$C, 0), 1), "")} | P16: {=IFERROR(INDEX(Skill!$AP:$AP, MATCH(P$4, Skill!$C:$C, 0), 1), "")} | Q16: {=IFERROR(INDEX(Skill!$AP:$AP, MATCH(Q$4, Skill!$C:$C, 0), 1), "")} -> 1000 | R16: {=IFERROR(INDEX(Skill!$AP:$AP, MATCH(R$4, Skill!$C:$C, 0), 1), "")} | ... ED16: {=IFERROR(INDEX(Skill!$AP:$AP, MATCH(ED$4, Skill!$C:$C, 0), 1), "")}
E17: Precondition | K17: {=IFERROR(INDEX(Skill!$U:$U, MATCH(K$4, Skill!$C:$C, 0), 1), "")} | L17: {=IFERROR(INDEX(Skill!$U:$U, MATCH(L$4, Skill!$C:$C, 0), 1), "")} | M17: {=IFERROR(INDEX(Skill!$U:$U, MATCH(M$4, Skill!$C:$C, 0), 1), "")} | N17: {=IFERROR(INDEX(Skill!$U:$U, MATCH(N$4, Skill!$C:$C, 0), 1), "")} -> ランパート|センチネル|エクストリームガード | O17: {=IFERROR(INDEX(Skill!$U:$U, MATCH(O$4, Skill!$C:$C, 0), 1), "")} | P17: {=IFERROR(INDEX(Skill!$U:$U, MATCH(P$4, Skill!$C:$C, 0), 1), "")} | Q17: {=IFERROR(INDEX(Skill!$U:$U, MATCH(Q$4, Skill!$C:$C, 0), 1), "")} | R17: {=IFERROR(INDEX(Skill!$U:$U, MATCH(R$4, Skill!$C:$C, 0), 1), "")} | ... ED17: {=IFERROR(INDEX(Skill!$U:$U, MATCH(ED$4, Skill!$C:$C, 0), 1), "")}
E18: Physical | K18: {=IFERROR(INDEX(Skill!$X:$X, MATCH(K$4, Skill!$C:$C, 0), 1), "")} | L18: {=IFERROR(INDEX(Skill!$X:$X, MATCH(L$4, Skill!$C:$C, 0), 1), "")} | M18: {=IFERROR(INDEX(Skill!$X:$X, MATCH(M$4, Skill!$C:$C, 0), 1), "")} | N18: {=IFERROR(INDEX(Skill!$X:$X, MATCH(N$4, Skill!$C:$C, 0), 1), "")} -> 0.8 | O18: {=IFERROR(INDEX(Skill!$X:$X, MATCH(O$4, Skill!$C:$C, 0), 1), "")} | P18: {=IFERROR(INDEX(Skill!$X:$X, MATCH(P$4, Skill!$C:$C, 0), 1), "")} | Q18: {=IFERROR(INDEX(Skill!$X:$X, MATCH(Q$4, Skill!$C:$C, 0), 1), "")} | R18: {=IFERROR(INDEX(Skill!$X:$X, MATCH(R$4, Skill!$C:$C, 0), 1), "")} | ... ED18: {=IFERROR(INDEX(Skill!$X:$X, MATCH(ED$4, Skill!$C:$C, 0), 1), "")}
E19: Magic | K19: {=IFERROR(INDEX(Skill!$W:$W, MATCH(K$4, Skill!$C:$C, 0), 1), "")} | L19: {=IFERROR(INDEX(Skill!$W:$W, MATCH(L$4, Skill!$C:$C, 0), 1), "")} | M19: {=IFERROR(INDEX(Skill!$W:$W, MATCH(M$4, Skill!$C:$C, 0), 1), "")} | N19: {=IFERROR(INDEX(Skill!$W:$W, MATCH(N$4, Skill!$C:$C, 0), 1), "")} -> 0.8 | O19: {=IFERROR(INDEX(Skill!$W:$W, MATCH(O$4, Skill!$C:$C, 0), 1), "")} | P19: {=IFERROR(INDEX(Skill!$W:$W, MATCH(P$4, Skill!$C:$C, 0), 1), "")} | Q19: {=IFERROR(INDEX(Skill!$W:$W, MATCH(Q$4, Skill!$C:$C, 0), 1), "")} | R19: {=IFERROR(INDEX(Skill!$W:$W, MATCH(R$4, Skill!$C:$C, 0), 1), "")} | ... ED19: {=IFERROR(INDEX(Skill!$W:$W, MATCH(ED$4, Skill!$C:$C, 0), 1), "")}
E20: Unique | K20: {=IFERROR(INDEX(Skill!$Y:$Y, MATCH(K$4, Skill!$C:$C, 0), 1), "")} | L20: {=IFERROR(INDEX(Skill!$Y:$Y, MATCH(L$4, Skill!$C:$C, 0), 1), "")} | M20: {=IFERROR(INDEX(Skill!$Y:$Y, MATCH(M$4, Skill!$C:$C, 0), 1), "")} | N20: {=IFERROR(INDEX(Skill!$Y:$Y, MATCH(N$4, Skill!$C:$C, 0), 1), "")} -> 0.8 | O20: {=IFERROR(INDEX(Skill!$Y:$Y, MATCH(O$4, Skill!$C:$C, 0), 1), "")} | P20: {=IFERROR(INDEX(Skill!$Y:$Y, MATCH(P$4, Skill!$C:$C, 0), 1), "")} | Q20: {=IFERROR(INDEX(Skill!$Y:$Y, MATCH(Q$4, Skill!$C:$C, 0), 1), "")} | R20: {=IFERROR(INDEX(Skill!$Y:$Y, MATCH(R$4, Skill!$C:$C, 0), 1), "")} | ... ED20: {=IFERROR(INDEX(Skill!$Y:$Y, MATCH(ED$4, Skill!$C:$C, 0), 1), "")}
E21: Barrier | K21: {=IFERROR(INDEX(Skill!$AB:$AB, MATCH(K$4, Skill!$C:$C, 0), 1), "")} | L21: {=IFERROR(INDEX(Skill!$AB:$AB, MATCH(L$4, Skill!$C:$C, 0), 1), "")} | M21: {=IFERROR(INDEX(Skill!$AB:$AB, MATCH(M$4, Skill!$C:$C, 0), 1), "")} | N21: {=IFERROR(INDEX(Skill!$AB:$AB, MATCH(N$4, Skill!$C:$C, 0), 1), "")} | O21: {=IFERROR(INDEX(Skill!$AB:$AB, MATCH(O$4, Skill!$C:$C, 0), 1), "")} | P21: {=IFERROR(INDEX(Skill!$AB:$AB, MATCH(P$4, Skill!$C:$C, 0), 1), "")} | Q21: {=IFERROR(INDEX(Skill!$AB:$AB, MATCH(Q$4, Skill!$C:$C, 0), 1), "")} | R21: {=IFERROR(INDEX(Skill!$AB:$AB, MATCH(R$4, Skill!$C:$C, 0), 1), "")} | ... ED21: {=IFERROR(INDEX(Skill!$AB:$AB, MATCH(ED$4, Skill!$C:$C, 0), 1), "")}
B22: Phase | C22: Time | E22: Action | F22: Type | H22: Damage | K22: Mitigation | EE22: Calculate | ER22: Total Damage | ET22: HP Bar | EU22: Calculate | EY22: HP Bar | EZ22: Calculate | FD22: HP Bar | FE22: Calculate | FI22: HP Bar | FJ22: Calculate | FN22: HP Bar
K23: =IMAGE("https://xivapi.com/i/062000/062119.png") | T23: =IMAGE("https://xivapi.com/i/062000/062121.png") | AC23: =IMAGE("https://xivapi.com/i/062000/062132.png") | AL23: =IMAGE("https://xivapi.com/i/062000/062137.png") | AS23: =IMAGE("https://xivapi.com/i/062000/062124.png") | BE23: =IMAGE("https://xivapi.com/i/062000/062133.png") | BY23: =IMAGE("https://xivapi.com/i/062000/062128.png") | CT23: =IMAGE("https://xivapi.com/i/062000/062140.png") | DJ23: =IMAGE("https://xivapi.com/i/062000/062120.png") | DL23: =IMAGE("https://xivapi.com/i/062000/062122.png") | DM23: =IMAGE("https://xivapi.com/i/062000/062130.png") | DN23: =IMAGE("https://xivapi.com/i/062000/062134.png") | DO23: =IMAGE("https://xivapi.com/i/062000/062139.png") | DP23: =IMAGE("https://xivapi.com/i/062000/062141.png") | DQ23: =IMAGE("https://xivapi.com/i/062000/062123.png") | DS23: =IMAGE("https://xivapi.com/i/062000/062131.png") | DU23: =IMAGE("https://xivapi.com/i/062000/062138.png") | DW23: =IMAGE("https://xivapi.com/i/062000/062125.png") | DX23: =IMAGE("https://xivapi.com/i/062000/062127.png") | DY23: =IMAGE("https://xivapi.com/i/062000/062135.png") | EA23: =IMAGE("https://xivapi.com/i/062000/062142.png") | ED23: =IMAGE("https://xivapi.com/cj/misc/bordered_tank.png") | EE23: Mitigation | EF23: Heal Buff (PARTY) | EH23: Heal Buff (WHM) | EJ23: Heal Buff (AST) | EL23: Heal Buff (SCH) | EN23: Heal Buff (SGE) | EP23: Mitigated Hit Damage | EQ23: Total Barrier | ET23: MAX HP | EU23: =IMAGE("https://xivapi.com/cj/companion/paladin.png") | EZ23: =IMAGE("https://xivapi.com/cj/companion/warrior.png") | FE23: =IMAGE("https://xivapi.com/cj/companion/darkknight.png") | FJ23: =IMAGE("https://xivapi.com/cj/companion/gunbreaker.png")
H24: Hit | I24: DoT | J24: tick | K24: {=IFERROR(INDEX(Skill!$D:$D, MATCH(K$4, Skill!$C:$C, 0), 1), "")} | L24: {=IFERROR(INDEX(Skill!$D:$D, MATCH(L$4, Skill!$C:$C, 0), 1), "")} | N24: {=IFERROR(INDEX(Skill!$D:$D, MATCH(N$4, Skill!$C:$C, 0), 1), "")} | O24: {=IFERROR(INDEX(Skill!$D:$D, MATCH(O$4, Skill!$C:$C, 0), 1), "")} | P24: {=IFERROR(INDEX(Skill!$D:$D, MATCH(P$4, Skill!$C:$C, 0), 1), "")} | Q24: {=IFERROR(INDEX(Skill!$D:$D, MATCH(Q$4, Skill!$C:$C, 0), 1), "")} | R24: {=IFERROR(INDEX(Skill!$D:$D, MATCH(R$4, Skill!$C:$C, 0), 1), "")} | S24: {=IFERROR(INDEX(Skill!$D:$D, MATCH(S$4, Skill!$C:$C, 0), 1), "")} | T24: {=IFERROR(INDEX(Skill!$D:$D, MATCH(T$4, Skill!$C:$C, 0), 1), "")} | U24: {=IFERROR(INDEX(Skill!$D:$D, MATCH(U$4, Skill!$C:$C, 0), 1), "")} | ... AF24: {=IFERROR(INDEX(Skill!$D:$D, MATCH(AF$4, Skill!$C:$C, 0), 1), "")} | AH24: {=IFERROR(INDEX(Skill!$D:$D, MATCH(AH$4, Skill!$C:$C, 0), 1), "")} | AI24: {=IFERROR(INDEX(Skill!$D:$D, MATCH(AI$4, Skill!$C:$C, 0), 1), "")} | AJ24: {=IFERROR(INDEX(Skill!$D:$D, MATCH(AJ$4, Skill!$C:$C, 0), 1), "")} | AK24: {=IFERROR(INDEX(Skill!$D:$D, MATCH(AK$4, Skill!$C:$C, 0), 1), "")} | AL24: {=IFERROR(INDEX(Skill!$D:$D, MATCH(AL$4, Skill!$C:$C, 0), 1), "")} | AM24: {=IFERROR(INDEX(Skill!$D:$D, MATCH(AM$4, Skill!$C:$C, 0), 1), "")} | AN24: {=IFERROR(INDEX(Skill!$D:$D, MATCH(AN$4, Skill!$C:$C, 0), 1), "")} | AO24: {=IFERROR(INDEX(Skill!$D:$D, MATCH(AO$4, Skill!$C:$C, 0), 1), "")} | ... AZ24: {=IFERROR(INDEX(Skill!$D:$D, MATCH(AZ$4, Skill!$C:$C, 0), 1), "")} | BB24: {=IFERROR(INDEX(Skill!$D:$D, MATCH(BB$4, Skill!$C:$C, 0), 1), "")} | BD24: {=IFERROR(INDEX(Skill!$D:$D, MATCH(BD$4, Skill!$C:$C, 0), 1), "")} | BE24: {=IFERROR(INDEX(Skill!$D:$D, MATCH(BE$4, Skill!$C:$C, 0), 1), "")} | BF24: {=IFERROR(INDEX(Skill!$D:$D, MATCH(BF$4, Skill!$C:$C, 0), 1), "")} | BG24: {=IFERROR(INDEX(Skill!$D:$D, MATCH(BG$4, Skill!$C:$C, 0), 1), "")} | BH24: {=IFERROR(INDEX(Skill!$D:$D, MATCH(BH$4, Skill!$C:$C, 0), 1), "")} | BI24: {=IFERROR(INDEX(Skill!$D:$D, MATCH(BI$4, Skill!$C:$C, 0), 1), "")} | BJ24: {=IFERROR(INDEX(Skill!$D:$D, MATCH(BJ$4, Skill!$C:$C, 0), 1), "")} | BK24: {=IFERROR(INDEX(Skill!$D:$D, MATCH(BK$4, Skill!$C:$C, 0), 1), "")} | ... BS24: {=IFERROR(INDEX(Skill!$D:$D, MATCH(BS$4, Skill!$C:$C, 0), 1), "")} | BU24: {=IFERROR(INDEX(Skill!$D:$D, MATCH(BU$4, Skill!$C:$C, 0), 1), "")} | BV24: {=IFERROR(INDEX(Skill!$D:$D, MATCH(BV$4, Skill!$C:$C, 0), 1), "")} | BX24: {=IFERROR(INDEX(Skill!$D:$D, MATCH(BX$4, Skill!$C:$C, 0), 1), "")} | BY24: {=IFERROR(INDEX(Skill!$D:$D, MATCH(BY$4, Skill!$C:$C, 0), 1), "")} | BZ24: {=IFERROR(INDEX(Skill!$D:$D, MATCH(BZ$4, Skill!$C:$C, 0), 1), "")} | CA24: {=IFERROR(INDEX(Skill!$D:$D, MATCH(CA$4, Skill!$C:$C, 0), 1), "")} | CB24: {=IFERROR(INDEX(Skill!$D:$D, MATCH(CB$4, Skill!$C:$C, 0), 1), "")} | CC24: {=IFERROR(INDEX(Skill!$D:$D, MATCH(CC$4, Skill!$C:$C, 0), 1), "")} | CD24: {=IFERROR(INDEX(Skill!$D:$D, MATCH(CD$4, Skill!$C:$C, 0), 1), "")} | CE24: {=IFERROR(INDEX(Skill!$D:$D, MATCH(CE$4, Skill!$C:$C, 0), 1), "")} | ... CR24: {=IFERROR(INDEX(Skill!$D:$D, MATCH(CR$4, Skill!$C:$C, 0), 1), "")} | CS24: =IMAGE("http://drive.google.com/uc?export=view&id=1AdMXq2oDpA84xtFE73ql3oAKBb8YsCwr") | CT24: {=IFERROR(INDEX(Skill!$D:$D, MATCH(CT$4, Skill!$C:$C, 0), 1), "")} | CU24: {=IFERROR(INDEX(Skill!$D:$D, MATCH(CU$4, Skill!$C:$C, 0), 1), "")} | CV24: {=IFERROR(INDEX(Skill!$D:$D, MATCH(CV$4, Skill!$C:$C, 0), 1), "")} | CW24: {=IFERROR(INDEX(Skill!$D:$D, MATCH(CW$4, Skill!$C:$C, 0), 1), "")} | CX24: {=IFERROR(INDEX(Skill!$D:$D, MATCH(CX$4, Skill!$C:$C, 0), 1), "")} | CY24: {=IFERROR(INDEX(Skill!$D:$D, MATCH(CY$4, Skill!$C:$C, 0), 1), "")} | CZ24: {=IFERROR(INDEX(Skill!$D:$D, MATCH(CZ$4, Skill!$C:$C, 0), 1), "")} | DA24: {=IFERROR(INDEX(Skill!$D:$D, MATCH(DA$4, Skill!$C:$C, 0), 1), "")} | ... DH24: {=IFERROR(INDEX(Skill!$D:$D, MATCH(DH$4, Skill!$C:$C, 0), 1), "")} | DI24: =IMAGE("http://drive.google.com/uc?export=view&id=1FcMZkz9P-d2sGOIP9AD8bApVpM0bcRKd") | DJ24: {=IFERROR(INDEX(Skill!$D:$D, MATCH(DJ$4, Skill!$C:$C, 0), 1), "")} | DK24: {=IFERROR(INDEX(Skill!$D:$D, MATCH(DK$4, Skill!$C:$C, 0), 1), "")} | DL24: {=IFERROR(INDEX(Skill!$D:$D, MATCH(DL$4, Skill!$C:$C, 0), 1), "")} | DM24: {=IFERROR(INDEX(Skill!$D:$D, MATCH(DM$4, Skill!$C:$C, 0), 1), "")} | DN24: {=IFERROR(INDEX(Skill!$D:$D, MATCH(DN$4, Skill!$C:$C, 0), 1), "")} | DO24: {=IFERROR(INDEX(Skill!$D:$D, MATCH(DO$4, Skill!$C:$C, 0), 1), "")} | DP24: {=IFERROR(INDEX(Skill!$D:$D, MATCH(DP$4, Skill!$C:$C, 0), 1), "")} | DQ24: {=IFERROR(INDEX(Skill!$D:$D, MATCH(DQ$4, Skill!$C:$C, 0), 1), "")} | ... ED24: {=IFERROR(INDEX(Skill!$D:$D, MATCH(ED$4, Skill!$C:$C, 0), 1), "")} | EF24: ALL | EG24: GCD | EH24: ALL | EI24: GCD | EJ24: ALL | EK24: GCD | EL24: ALL | EM24: GCD | EN24: ALL | EO24: GCD | ER24: Hit | ES24: DoT | ET24: =Option!$D$21 -> 142000 | EU24: Mitigation | EV24: Damage | EW24: Heal Buff | EX24: Barrier | EY24: =Option!$D$17 -> 225800 | EZ24: Mitigation | FA24: Damage | FB24: Heal Buff | FC24: Barrier | FD24: =Option!$D$18 -> 225800 | FE24: Mitigation | FF24: Damage | FG24: Heal Buff | FH24: Barrier | FI24: =Option!$D$19 -> 225800 | FJ24: Mitigation | FK24: Damage | FL24: Heal Buff | FM24: Barrier | FN24: =Option!$D$20 -> 225800
C25: =IFERROR(C$3+D25, D25) -> -0.00023148148 | D25: -0.00023148148 | E25: =SWITCH(Option!C3, "日本語", "戦闘開始まで20秒", "English", "Battle commencing in 20 seconds!", "Deutsch", "Noch 20 Sekunden bis Kampfbeginn!", "Français", "Début du combat dans 20 secondes!", "한국어", "Battle commencing in 20 seconds!", "简体中文", "Battle commencing in 20 seconds!", "戦闘開始まで20秒") -> Battle commencing in 20 seconds! | G25: =SWITCH(F25, "Physical", image("https://xivapi.com/i/060000/060011.png"), "Magic", image("https://xivapi.com/i/060000/060012.png"), "Unique", image("https://xivapi.com/i/060000/060013.png"), "") | K25: FALSE | L25: FALSE | M25: FALSE | N25: - | O25: FALSE | P25: FALSE | Q25: FALSE | R25: FALSE | S25: FALSE | T25: FALSE | U25: FALSE | V25: - | W25: FALSE | X25: FALSE | Y25: FALSE | Z25: FALSE | AA25: FALSE | AB25: FALSE | AC25: FALSE | AD25: FALSE | AE25: - | AF25: - | AG25: =IFERROR(__xludf.DUMMYFUNCTION("IF( ISNUMBER(AG24), MIN(MAX( AG24 + MAX( ROUNDDOWN(($D25 - MAX(IFERROR(FILTER($D$24:$D24, AG$24:AG24 <> AF$6, AG$23:AG23 = AF$6), 0))) * (60 * 60 * 24) / AF$9) - ROUNDDOWN(($D24 - MAX(IFERROR(FILTER($D$23:$D23, AG$23:AG23 <> AF$6, AG$22:"&"AG22 = AF$6), 0))) * (60 * 60 * 24) / 60), 0 ) - COUNTIF(AF25, ""<>-""), 0), AF$6), AF$6 - COUNTIF(AF25, ""<>-"") )"),2.0) -> 2 | AH25: FALSE | AI25: FALSE | AJ25: FALSE | AK25: FALSE | AL25: FALSE | AM25: FALSE | AN25: - | AO25: FALSE | AP25: FALSE | AQ25: FALSE | AR25: FALSE | AS25: FALSE | AT25: FALSE | AU25: FALSE | AV25: FALSE | AW25: FALSE | AX25: FALSE | AY25: - | AZ25: - | BA25: =IFERROR(__xludf.DUMMYFUNCTION("IF( ISNUMBER(BA24), MIN(MAX( BA24 + MAX( ROUNDDOWN(($D25 - MAX(IFERROR(FILTER($D$24:$D24, BA$24:BA24 <> AZ$6, BA$23:BA23 = AZ$6), 0))) * (60 * 60 * 24) / AZ$9) - ROUNDDOWN(($D24 - MAX(IFERROR(FILTER($D$23:$D23, BA$23:BA23 <> AZ$6, BA$22:"&"BA22 = AZ$6), 0))) * (60 * 60 * 24) / 60), 0 ) - COUNTIF(AZ25, ""<>-""), 0), AZ$6), AZ$6 - COUNTIF(AZ25, ""<>-"") )"),2.0) -> 2 | BB25: - | BC25: =IFERROR(__xludf.DUMMYFUNCTION("IF( ISNUMBER(BC24), MIN(MAX( BC24 + MAX( ROUNDDOWN(($D25 - MAX(IFERROR(FILTER($D$24:$D24, BC$24:BC24 <> BB$6, BC$23:BC23 = BB$6), 0))) * (60 * 60 * 24) / BB$9) - ROUNDDOWN(($D24 - MAX(IFERROR(FILTER($D$23:$D23, BC$23:BC23 <> BB$6, BC$22:"&"BC22 = BB$6), 0))) * (60 * 60 * 24) / 60), 0 ) - COUNTIF(BB25, ""<>-""), 0), BB$6), BB$6 - COUNTIF(BB25, ""<>-"") )"),2.0) -> 2 | BD25: - | BE25: FALSE | BF25: FALSE | BG25: FALSE | BH25: FALSE | BI25: FALSE | BJ25: FALSE | BK25: FALSE | BL25: FALSE | BM25: FALSE | BN25: FALSE | BO25: - | BP25: - | BQ25: - | BR25: - | BS25: - | BT25: =IFERROR(__xludf.DUMMYFUNCTION("IF( ISNUMBER(BT24), MIN(MAX( BT24 + MAX( ROUNDDOWN(($D25 - MAX(IFERROR(FILTER($D$24:$D24, BT$24:BT24 <> BS$6, BT$23:BT23 = BS$6), 0))) * (60 * 60 * 24) / BS$9) - ROUNDDOWN(($D24 - MAX(IFERROR(FILTER($D$23:$D23, BT$23:BT23 <> BS$6, BT$22:"&"BT22 = BS$6), 0))) * (60 * 60 * 24) / 60), 0 ) - COUNTIF(BS25, ""<>-""), 0), BS$6), BS$6 - COUNTIF(BS25, ""<>-"") )"),3.0) -> 3 | BU25: - | BV25: - | BW25: =IFERROR(__xludf.DUMMYFUNCTION("IF( ISNUMBER(BW24), MIN(MAX( BW24 + MAX( ROUNDDOWN(($D25 - MAX(IFERROR(FILTER($D$24:$D24, BW$24:BW24 <> BV$6, BW$23:BW23 = BV$6), 0))) * (60 * 60 * 24) / BV$9) - ROUNDDOWN(($D24 - MAX(IFERROR(FILTER($D$23:$D23, BW$23:BW23 <> BV$6, BW$22:"&"BW22 = BV$6), 0))) * (60 * 60 * 24) / 60), 0 ) - COUNTIF(BV25, ""<>-""), 0), BV$6), BV$6 - COUNTIF(BV25, ""<>-"") )"),2.0) -> 2 | BX25: - | BY25: FALSE | BZ25: FALSE | CA25: FALSE | CB25: FALSE | CC25: FALSE | CD25: FALSE | CE25: FALSE | CF25: FALSE | CG25: FALSE | CH25: FALSE | CI25: FALSE | CJ25: FALSE | CK25: FALSE | CL25: FALSE | CM25: - | CN25: - | CO25: - | CP25: - | CQ25: - | CR25: FALSE | CS25: =SWITCH( IF(OR(AND(CI25, CI24<>TRUE), CR25), 3, IF(ISTEXT(CS24), FIND("◇", CS24&"◇") - 1, 0)) - COUNTIFS({BZ25,CE25}, "=TRUE", {BZ24,CE24}, "<>TRUE") - COUNTIF({CN25,CQ25}, "<>-") + IF(COUNTIFS({BZ25,CE25}, "=TRUE", {BZ24,CE24}, "<>TRUE") + COUNTIF({CN25,CQ25}, "<>-"), COUNTIFS(CJ25, "=TRUE", CJ24, "<>TRUE"), 0), 0, "◇◇◇", 1, "◆◇◇", 2, "◆◆◇", 3, "◆◆◆", "◇◇◇" ) -> ◇◇◇ | CT25: FALSE | CU25: FALSE | CV25: FALSE | CW25: FALSE | CX25: FALSE | CY25: FALSE | CZ25: FALSE | DA25: FALSE | DB25: FALSE | DC25: FALSE | DD25: - | DE25: - | DF25: - | DG25: - | DH25: FALSE | DI25: =IFERROR(__xludf.DUMMYFUNCTION("SWITCH( IF( ISTEXT(DI24), IF ( FIND(""○"", DI24&""○"") > 3, 3, FIND(""○"", DI24&""○"") + MAX( ROUNDDOWN(($D25 - MAX(IFERROR(FILTER(D$24:D24, DI$24:DI24 <> ""●●●"", DI$23:DI23 = ""●●●""), 0))) * (60 * 60 * 24) / 20"&") - ROUNDDOWN(($D24 - MAX(IFERROR(FILTER(D$23:D23, DI$23:DI23 <> ""●●●"", DI$22:DI22 = ""●●●""), 0))) * (60 * 60 * 24) / 20), 0 ) - 1 ) - COUNTIFS(CU25, ""=TRUE"", CU24, ""<>TRUE"") - COUNTIF(CZ25, ""=TRUE"") - COUNTIF({DD25,DE25}, ""<>-"&""") + COUNTIF(DH25, ""=TRUE""), 3 ), 0, ""○○○"", 1, ""●○○"", 2, ""●●○"", 3, ""●●●"", 4, ""●●●"", ""○○○"" )"),"●●●") -> ●●● | DJ25: FALSE | DK25: FALSE | DL25: FALSE | DM25: FALSE | DN25: FALSE | DO25: FALSE | DP25: FALSE | DQ25: FALSE | DR25: FALSE | DS25: FALSE | DT25: FALSE | DU25: FALSE | DV25: - | DW25: FALSE | DX25: FALSE | DY25: FALSE | DZ25: FALSE | EA25: FALSE | EB25: FALSE | EC25: FALSE | ED25: FALSE | EE25: =IFERROR(__xludf.DUMMYFUNCTION("IFERROR( PRODUCT( MAP( INDEX(TRANSPOSE(UNIQUE(TRANSPOSE(FILTER({IF($F25=""Physical"", K$10:ED$10, IF($F25=""Magic"", K$11:ED$11, K$12:ED$12));K$4:ED$4;K25:ED25}, K25:ED25=TRUE)))), 1, 0), INDEX(TRANSPOSE(UNIQUE(TRANSPOSE(FILTER({IF($"&"F25=""Physical"", K$18:ED$18, IF($F25=""Magic"", K$19:ED$19, K$20:ED$20));K$4:ED$4;K25:ED25}, K25:ED25=TRUE)))), 1, 0), INDEX(TRANSPOSE(UNIQUE(TRANSPOSE(FILTER({K$5:ED$5;K$4:ED$4;K25:ED25}, K25:ED25=TRUE)))), 1, 0), INDEX(TRANSPOSE(UNIQUE(TR"&"ANSPOSE(FILTER({K$17:ED$17;K$4:ED$4;K25:ED25}, K25:ED25=TRUE)))), 1, 0), LAMBDA( mitigation, enhance, assign, precondition, IF( REGEXMATCH(assign, ""RANGE_PARTY|SINGLE_ENEMY|RANGE_ENEMY""), "&" IF( OR(ARRAYFORMULA((IF(precondition="""", FALSE, REGEXMATCH(K$4:ED$4, precondition))) * (K25:ED25=TRUE))), IF(ISNUMBER(enhance), enhance, 1), IF(ISNUMBER(mitigation), mitigation, 1) ), "&" 1 ) ) ) ), 1 )"),1.0) -> 1 | EF25: =IFERROR(__xludf.DUMMYFUNCTION("PRODUCT( MAP( K$14:ED$14, K$13:ED$13, K25:ED25, LAMBDA( buff, target, check, IF( AND(check=TRUE, REGEXMATCH(target, ""RANGE_AFFECTED_ALL|RANGE_EFFECTED_ALL""), ISNUMBER(buff)), buff, "&" 1 ) ) ) )"),1.0) -> 1 | EG25: =IFERROR(__xludf.DUMMYFUNCTION("PRODUCT( MAP( K$14:ED$14, K$13:ED$13, K25:ED25, LAMBDA( buff, target, check, IF( AND(check=TRUE, REGEXMATCH(target, ""RANGE_AFFECTED_GCD|RANGE_EFFECTED_GCD""), ISNUMBER(buff)), buff, "&" 1 ) ) ) )"),1.0) -> 1 | EH25: =IFERROR(__xludf.DUMMYFUNCTION("PRODUCT( MAP( K$3:ED$3, K$14:ED$14, K$13:ED$13, K25:ED25, LAMBDA( job, buff, target, check, IF( AND(check=TRUE, REGEXMATCH(target, ""SELF_EFFECTED_ALL""), ISNUMBER(buff), job=""白魔道士"""&"), buff, 1 ) ) ) )"),1.0) -> 1 | EI25: =IFERROR(__xludf.DUMMYFUNCTION("PRODUCT( MAP( K$3:ED$3, K$14:ED$14, K$13:ED$13, K25:ED25, LAMBDA( job, buff, target, check, IF( AND(check=TRUE, REGEXMATCH(target, ""SELF_EFFECTED_GCD""), ISNUMBER(buff), job=""白魔道士"""&"), buff, 1 ) ) ) )"),1.0) -> 1 | EJ25: =IFERROR(__xludf.DUMMYFUNCTION("PRODUCT( MAP( K$3:ED$3, K$14:ED$14, K$13:ED$13, K25:ED25, LAMBDA( job, buff, target, check, IF( AND(check=TRUE, REGEXMATCH(target, ""SELF_EFFECTED_ALL""), ISNUMBER(buff), job=""占星術師"""&"), buff, 1 ) ) ) )"),1.0) -> 1 | EK25: =IFERROR(__xludf.DUMMYFUNCTION("PRODUCT( MAP( K$3:ED$3, K$14:ED$14, K$13:ED$13, K25:ED25, LAMBDA( job, buff, target, check, IF( AND(check=TRUE, REGEXMATCH(target, ""SELF_EFFECTED_GCD""), ISNUMBER(buff), job=""占星術師"""&"), buff, 1 ) ) ) )"),1.0) -> 1 | EL25: =IFERROR(__xludf.DUMMYFUNCTION("PRODUCT( MAP( K$3:ED$3, K$14:ED$14, K$13:ED$13, K25:ED25, LAMBDA( job, buff, target, check, IF( AND(check=TRUE, REGEXMATCH(target, ""SELF_EFFECTED_ALL""), ISNUMBER(buff), job=""学者""),"&" buff, 1 ) ) ) )"),1.0) -> 1 | EM25: =IFERROR(__xludf.DUMMYFUNCTION("PRODUCT( MAP( K$3:ED$3, K$14:ED$14, K$13:ED$13, K25:ED25, LAMBDA( job, buff, target, check, IF( AND(check=TRUE, REGEXMATCH(target, ""SELF_EFFECTED_GCD""), ISNUMBER(buff), job=""学者""),"&" buff, 1 ) ) ) )"),1.0) -> 1 | EN25: =IFERROR(__xludf.DUMMYFUNCTION("PRODUCT( MAP( K$3:ED$3, K$14:ED$14, K$13:ED$13, K25:ED25, LAMBDA( job, buff, target, check, IF( AND(check=TRUE, REGEXMATCH(target, ""SELF_EFFECTED_ALL""), ISNUMBER(buff), job=""賢者""),"&" buff, 1 ) ) ) )"),1.0) -> 1 | EO25: =IFERROR(__xludf.DUMMYFUNCTION("PRODUCT( MAP( K$3:ED$3, K$14:ED$14, K$13:ED$13, K25:ED25, LAMBDA( job, buff, target, check, IF( AND(check=TRUE, REGEXMATCH(target, ""SELF_EFFECTED_GCD""), ISNUMBER(buff), job=""賢者""),"&" buff, 1 ) ) ) )"),1.0) -> 1 | EP25: =H25*EE25 -> 0 | EQ25: =IFERROR(__xludf.DUMMYFUNCTION("SUM( MAP( K$4:ED$4, K$3:ED$3, K$7:ED$7, K$15:ED$15, K$16:ED$16, K$21:ED$21, K$5:ED$5, K$17:ED$17, K25:ED25, LAMBDA( name, job, abillity, buff, barrier, enhance,"&" assign, precondition, check, SWITCH( name, ""シェイクオフ"", IF(check=TRUE, buff + (0.02 * COUNTIF(ARRAYFORMULA((REGEXMATCH($K$4:$ED$4, ""スリル・オブ・バトル|ヴェンジェンス|原初の血気|ダムネーション"")) * (K25:ED25=TRUE)), 1)), 0), "&"""インプロビゼーションフィニッシュ(踊りの激情0)"", IF(ISNUMBER(check), INDEX(Skill!$AJ:$AJ, MATCH(SUBSTITUTE(DV$4, 0, check), Skill!$C:$C, 0)), 0), IF( AND(check=TRUE, REGEXMATCH(assign, ""RANGE_PARTY"")), IF( OR(ARRAYFORMULA((IF(pr"&"econdition="""", FALSE, REGEXMATCH($K$4:$ED$4, precondition))) * (K25:ED25=TRUE))), enhance, IF(barrier="""", buff, barrier) ), 0 ) ) * SWITCH( job, ""ナイト"", EY$24, "&" ""戦士"", FD$24, ""踊り子"", ET$24, ""ピクトマンサー"", ET$24, ""白魔道士"", EF25 * EH25 * IF(abillity, 1, EG25 * EI25) * (Option!$D$22 * 0.81 / 100), ""占星術師"", EF25 * EJ25 * IF(abillity, 1, EG25 * EK25) * (Option!$D$23 * 0.81 "&"/ 100), ""学者"", EF25 * EL25 * IF(abillity, 1, EG25 * EM25) * (Option!$D$24 * 0.81 / 100), ""賢者"", EF25 * EN25 * IF(abillity, 1, EG25 * EO25) * (Option!$D$25 * 0.81 / 100), 1 ) ) ) )"),0.0) -> 0 | ER25: =IF(EP25 < EQ25, 0, EP25 - EQ25) -> 0 | ES25: =I25*J25*EE25 -> 0 | ET25: =IFERROR(__xludf.DUMMYFUNCTION("IFS( EP25 > $ET$24 + EQ25, SPARKLINE({ 1, 0 }, {""charttype"",""bar"";""max"", 1;""color1"",Option!$D$30;""color2"",Option!$D$30}), EP25 < EQ25, SPARKLINE({EQ25 - EP25, $ET$24 - (EQ25 - EP25)}, {""charttype"",""bar"";""max"",$ET$24;""color1"",Opti"&"on!$D$28;""color2"",Option!$D$29}), EP25 >= EQ25, SPARKLINE({$ET$24 + EQ25 - EP25,EP25 - EQ25}, {""charttype"",""bar"";""max"",$ET$24;""color1"",Option!$D$29;""color2"",Option!$D$30}) )"),"") | EU25: =IFERROR(__xludf.DUMMYFUNCTION("PRODUCT( MAP( IF($F25=""Physical"", K$10:ED$10, IF($F25=""Magic"", K$11:ED$11, K$12:ED$12)), IF($F25=""Physical"", K$18:ED$18, IF($F25=""Magic"", K$19:ED$19, K$20:ED$20)), K$3:ED$3, K$5:ED$5, K$17:ED$17, K25:ED25, LAM"&"BDA( mitigation, enhance, job, assign, precondition, check, IF( OR(AND(check=TRUE, REGEXMATCH(assign, ""SELF""), job=""ナイト""), AND(check=Option!$E$13, REGEXMATCH(assign, ""SINGLE_PARTY""))), "&" IF( OR(ARRAYFORMULA((IF(precondition="""", FALSE, REGEXMATCH($K$4:$ED$4, precondition))) * (K25:ED25=TRUE))), enhance, mitigation ), 1 ) ) ) ) * EE25"),1.0) -> 1 | EV25: =H25 * EU25 * 0.8 -> 0 | EW25: =IFERROR(__xludf.DUMMYFUNCTION("PRODUCT( MAP( K$3:ED$3, K$14:ED$14, K$13:ED$13, K25:ED25, LAMBDA( job, buff, target, check, IF( OR(AND(check=TRUE, REGEXMATCH(target, ""SELF_AFFECTED_ALL""), job=""ナイト""), AND(check=O"&"ption!$E$13, REGEXMATCH(target, ""SINGLE_AFFECTED_ALL""))), buff, 1 ) ) ) )"),1.0) -> 1 | EX25: =IFERROR(__xludf.DUMMYFUNCTION("SUM( MAP( K$3:ED$3, K$7:ED$7, K$15:ED$15, K$16:ED$16, K$21:ED$21, K$5:ED$5, K$17:ED$17, K25:ED25, LAMBDA( job, abillity, buff, barrier, enhance, assign, preco"&"ndition, check, IF( OR(AND(check=TRUE, REGEXMATCH(assign, ""SELF""), job=""ナイト""), AND(check=Option!$E$13, REGEXMATCH(assign, ""SINGLE_PARTY""))), IF( OR(ARRAYFORMULA((IF(precondition="""", FALSE, REGEXMATCH($K$4"&":$ED$4, precondition))) * (K25:ED25=TRUE))), enhance, IF(barrier="""", buff, barrier) ), 0 ) * SWITCH( job, ""暗黒騎士"", EY$24, ""白魔道士"", EF25 * EH25 * EW25 * IF(abillity, 1, EG"&"25 * EI25) * (Option!$D$22 * 0.81 / 100), ""占星術師"", EF25 * EJ25 * EW25 * IF(abillity, 1, EG25 * EK25) * (Option!$D$23 * 0.81 / 100), ""学者"", EF25 * EL25 * EW25 * IF(abillity, 1, EG25 * EM25) * (Option!$D$24 * 0.81 / 100), ""賢者"""&", EF25 * EN25 * EW25 * IF(abillity, 1, EG25 * EO25) * (Option!$D$25 * 0.81 / 100), 1 ) ) ) ) + EQ25"),0.0) -> 0 | EY25: =MAX(EV25 - EX25, 0) -> 0 | EZ25: =IFERROR(__xludf.DUMMYFUNCTION("PRODUCT( MAP( IF($F25=""Physical"", K$10:ED$10, IF($F25=""Magic"", K$11:ED$11, K$12:ED$12)), IF($F25=""Physical"", K$18:ED$18, IF($F25=""Magic"", K$19:ED$19, K$20:ED$20)), K$3:ED$3, K$5:ED$5, K$17:ED$17, K25:ED25, LAM"&"BDA( mitigation, enhance, job, assign, precondition, check, IF( OR(AND(check=TRUE, REGEXMATCH(assign, ""SELF""), job=""戦士""), AND(check=Option!$F$13, REGEXMATCH(assign, ""SINGLE_PARTY""))), "&" IF( OR(ARRAYFORMULA((IF(precondition="""", FALSE, REGEXMATCH($K$4:$ED$4, precondition))) * (K25:ED25=TRUE))), enhance, mitigation ), 1 ) ) ) ) * EE25"),1.0) -> 1 | FA25: =H25 * EZ25 * 0.8 -> 0 | FB25: =IFERROR(__xludf.DUMMYFUNCTION("PRODUCT( MAP( K$3:ED$3, K$14:ED$14, K$13:ED$13, K25:ED25, LAMBDA( job, buff, target, check, IF( OR(AND(check=TRUE, REGEXMATCH(target, ""SELF_AFFECTED_ALL""), job=""戦士""), AND(check=Op"&"tion!$F$13, REGEXMATCH(target, ""SINGLE_AFFECTED_ALL""))), buff, 1 ) ) ) )"),1.0) -> 1 | FC25: =IFERROR(__xludf.DUMMYFUNCTION("SUM( MAP( K$3:ED$3, K$7:ED$7, K$15:ED$15, K$16:ED$16, K$21:ED$21, K$5:ED$5, K$17:ED$17, K25:ED25, LAMBDA( job, abillity, buff, barrier, enhance, assign, preco"&"ndition, check, IF( OR(AND(check=TRUE, REGEXMATCH(assign, ""SELF""), job=""戦士""), AND(check=Option!$F$13, REGEXMATCH(assign, ""SINGLE_PARTY""))), IF( OR(ARRAYFORMULA((IF(precondition="""", FALSE, REGEXMATCH($K$4:"&"$ED$4, precondition))) * (K25:ED25=TRUE))), enhance, IF(barrier="""", buff, barrier) ), 0 ) * SWITCH( job, ""暗黒騎士"", FD$24, ""白魔道士"", EF25 * EH25 * FB25 * IF(abillity, 1, EG2"&"5 * EI25) * (Option!$D$22 * 0.81 / 100), ""占星術師"", EF25 * EJ25 * FFB25 * IF(abillity, 1, EG25 * EK25) * (Option!$D$23 * 0.81 / 100), ""学者"", EF25 * EL25 * FB25 * IF(abillity, 1, EG25 * EM25) * (Option!$D$24 * 0.81 / 100), ""賢者"""&", EF25 * EN25 * FB25 * IF(abillity, 1, EG25 * EO25) * (Option!$D$25 * 0.81 / 100), 1 ) ) ) ) + EQ25"),0.0) -> 0 | FD25: =MAX(FA25 - FC25, 0) -> 0 | FE25: =IFERROR(__xludf.DUMMYFUNCTION("PRODUCT( MAP( IF($F25=""Physical"", K$10:ED$10, IF($F25=""Magic"", K$11:ED$11, K$12:ED$12)), IF($F25=""Physical"", K$18:ED$18, IF($F25=""Magic"", K$19:ED$19, K$20:ED$20)), K$3:ED$3, K$5:ED$5, K$17:ED$17, K25:ED25, LAM"&"BDA( mitigation, enhance, job, assign, precondition, check, IF( OR(AND(check=TRUE, REGEXMATCH(assign, ""SELF""), job=""暗黒騎士""), AND(check=Option!$G$13, REGEXMATCH(assign, ""SINGLE_PARTY""))), "&" IF( OR(ARRAYFORMULA((IF(precondition="""", FALSE, REGEXMATCH($K$4:$ED$4, precondition))) * (K25:ED25=TRUE))), enhance, mitigation ), 1 ) ) ) ) * EE25"),1.0) -> 1 | FF25: =H25 * FE25 * 0.8 -> 0 | FG25: =IFERROR(__xludf.DUMMYFUNCTION("PRODUCT( MAP( K$3:ED$3, K$14:ED$14, K$13:ED$13, K25:ED25, LAMBDA( job, buff, target, check, IF( OR(AND(check=TRUE, REGEXMATCH(target, ""SELF_AFFECTED_ALL""), job=""暗黒騎士""), AND(check="&"Option!$G$13, REGEXMATCH(target, ""SINGLE_AFFECTED_ALL""))), buff, 1 ) ) ) )"),1.0) -> 1 | FH25: =IFERROR(__xludf.DUMMYFUNCTION("SUM( MAP( K$3:ED$3, K$7:ED$7, K$15:ED$15, K$16:ED$16, K$21:ED$21, K$5:ED$5, K$17:ED$17, K25:ED25, LAMBDA( job, abillity, buff, barrier, enhance, assign, preco"&"ndition, check, IF( OR(AND(check=TRUE, REGEXMATCH(assign, ""SELF""), job=""暗黒騎士""), AND(check=Option!$G$13, REGEXMATCH(assign, ""SINGLE_PARTY""))), IF( OR(ARRAYFORMULA((IF(precondition="""", FALSE, REGEXMATCH($K$"&"4:$ED$4, precondition))) * (K25:ED25=TRUE))), enhance, IF(barrier="""", buff, barrier) ), 0 ) * SWITCH( job, ""暗黒騎士"", FI$24, ""白魔道士"", EF25 * EH25 * FG25 * IF(abillity, 1, E"&"G25 * EI25) * (Option!$D$22 * 0.81 / 100), ""占星術師"", EF25 * EJ25 * FG25 * IF(abillity, 1, EG25 * EK25) * (Option!$D$23 * 0.81 / 100), ""学者"", EF25 * EL25 * FG25 * IF(abillity, 1, EG25 * EM25) * (Option!$D$24 * 0.81 / 100), ""賢者"&""", EF25 * EN25 * FG25 * IF(abillity, 1, EG25 * EO25) * (Option!$D$25 * 0.81 / 100), 1 ) ) ) ) + EQ25"),0.0) -> 0 | FI25: =MAX(FF25 - FH25, 0) -> 0 | FJ25: =IFERROR(__xludf.DUMMYFUNCTION("PRODUCT( MAP( IF($F25=""Physical"", K$10:ED$10, IF($F25=""Magic"", K$11:ED$11, K$12:ED$12)), IF($F25=""Physical"", K$18:ED$18, IF($F25=""Magic"", K$19:ED$19, K$20:ED$20)), K$3:ED$3, K$5:ED$5, K$17:ED$17, K25:ED25, LAM"&"BDA( mitigation, enhance, job, assign, precondition, check, IF( OR(AND(check=TRUE, REGEXMATCH(assign, ""SELF""), job=""ガンブレイカー""), AND(check=Option!$H$13, REGEXMATCH(assign, ""SINGLE_PARTY""))), "&" IF( OR(ARRAYFORMULA((IF(precondition="""", FALSE, REGEXMATCH($K$4:$ED$4, precondition))) * (K25:ED25=TRUE))), enhance, mitigation ), 1 ) ) ) ) * EE25"),1.0) -> 1 | FK25: =H25 * FJ25 * 0.8 -> 0 | FL25: =IFERROR(__xludf.DUMMYFUNCTION("PRODUCT( MAP( K$3:ED$3, K$14:ED$14, K$13:ED$13, K25:ED25, LAMBDA( job, buff, target, check, IF( OR(AND(check=TRUE, REGEXMATCH(target, ""SELF_AFFECTED_ALL""), job=""ガンブレイカー""), AND(che"&"ck=Option!$H$13, REGEXMATCH(target, ""SINGLE_AFFECTED_ALL""))), buff, 1 ) ) ) )"),1.0) -> 1 | FM25: =IFERROR(__xludf.DUMMYFUNCTION("SUM( MAP( K$3:ED$3, K$7:ED$7, K$15:ED$15, K$16:ED$16, K$21:ED$21, K$5:ED$5, K$17:ED$17, K25:ED25, LAMBDA( job, abillity, buff, barrier, enhance, assign, preco"&"ndition, check, IF( OR(AND(check=TRUE, REGEXMATCH(assign, ""SELF""), job=""ガンブレイカー""), AND(check=Option!$H$13, REGEXMATCH(assign, ""SINGLE_PARTY""))), IF( OR(ARRAYFORMULA((IF(precondition="""", FALSE, REGEXMATCH("&"$K$4:$ED$4, precondition))) * (K25:ED25=TRUE))), enhance, IF(barrier="""", buff, barrier) ), 0 ) * SWITCH( job, ""暗黒騎士"", FN$24, ""白魔道士"", EF25 * EH25 * FL25 * IF(abillity, 1"&", EG25 * EI25) * (Option!$D$22 * 0.81 / 100), ""占星術師"", EF25 * EJ25 * FL25 * IF(abillity, 1, EG25 * EK25) * (Option!$D$23 * 0.81 / 100), ""学者"", EF25 * EL25 * FL25 * IF(abillity, 1, EG25 * EM25) * (Option!$D$24 * 0.81 / 100), """&"賢者"", EF25 * EN25 * FL25 * IF(abillity, 1, EG25 * EO25) * (Option!$D$25 * 0.81 / 100), 1 ) ) ) ) + EQ25"),0.0) -> 0 | FN25: =MAX(FK25 - FM25, 0) -> 0
